Workbook
Name Slicer_City: #N/A
Name Slicer_City1: #N/A

Sheet Data
A1: Order_ID | B1: Customer_Name | C1: City | D1: Product | E1: Quantity | F1: Delivery_Status | G1: Delivery_Days
A2: 1001 | B2: Rahul Sharma | C2: Pune | D2: Laptop | E2: 2 | F2: Delivered | G2: 5
A3: 1002 | B3: Sneha Patil | C3: Mumbai | D3: Mouse | E3: 5 | F3: Pending | G3: 12
A4: 1003 | B4: Amit | C4: Delhi | D4: Keyboard | E4: 2 | F4: Delivered | G4: 4
A5: 1004 | B5: Priya | C5: Pune | D5: Monitor | E5: 1 | F5: Cancelled | G5: 0
A6: 1005 | B6: Missing | C6: Bangalore | D6: Laptop | E6: 3 | F6: Delivered | G6: 7
A7: 1006 | B7: Rohan Mehta | C7: Mumbai | D7: Phone | E7: 1 | F7: Delivered | G7: 3
A8: 1007 | B8: Kavya Singh | C8: Chennai | D8: Mouse | E8: 10 | F8: Pending | G8: 15
A9: 1008 | B9: Arjun | C9: Pune | D9: Tablet | E9: 2 | F9: Delivered | G9: 6
A10: 1009 | B10: Neha Verma | C10: Delhi | D10: Keyboard | E10: 0 | F10: Returned | G10: 9
A11: 1010 | B11: Vikas Patil | C11: Kolkata | D11: Laptop | E11: 1 | F11: Delivered | G11: 5
A12: 1011 | B12: Sameer Khan | C12: Pune | D12: Mouse | E12: 4 | F12: Pending | G12: 11
A13: 1012 | B13: Anjali | C13: Hyderabad | D13: Monitor | E13: 1 | F13: Delivered | G13: 3
... A21: 1020 | B21: Meena Joshi | C21: Chennai | D21: Monitor | E21: 2 | F21: Delivered | G21: 6

Sheet Chartes
A1: City-Wise Delivery Dashboard
A2: Source: Data sheet orders | Built for quick city, product, and delivery status review
A4: Total Orders | B4: Delivered % | C4: Pending Orders | D4: Cancelled Orders | E4: Returned Orders | F4: Avg Delivery Days | H4: At-a-glance view: tables on the left show exact values; charts on the right show patterns.
A5: =COUNTA(Data!$A$2:$A$21) -> 20 | B5: =COUNTIF(Data!$F$2:$F$21,"Delivered")/COUNTA(Data!$A$2:$A$21) -> 0.55 | C5: =COUNTIF(Data!$F$2:$F$21,"Pending") -> 5 | D5: =COUNTIF(Data!$F$2:$F$21,"Cancelled") -> 2 | E5: =COUNTIF(Data!$F$2:$F$21,"Returned") -> 2 | F5: =AVERAGE(Data!$G$2:$G$21) -> 6.6 | H5: Green = delivered, amber = pending, orange/red = exceptions.
A7: Table 1 — City Performance
A8: City | B8: Orders | C8: Quantity | D8: Delivered % | E8: Avg Delivery Days
A9: Bangalore | B9: =COUNTIF(Data!$C$2:$C$21,A9) -> 2 | C9: =SUMIF(Data!$C$2:$C$21,A9,Data!$E$2:$E$21) -> 4 | D9: =IFERROR(COUNTIFS(Data!$C$2:$C$21,A9,Data!$F$2:$F$21,"Delivered")/B9,0) -> 1 | E9: =AVERAGEIF(Data!$C$2:$C$21,A9,Data!$G$2:$G$21) -> 4.5
A10: Chennai | B10: =COUNTIF(Data!$C$2:$C$21,A10) -> 3 | C10: =SUMIF(Data!$C$2:$C$21,A10,Data!$E$2:$E$21) -> 14 | D10: =IFERROR(COUNTIFS(Data!$C$2:$C$21,A10,Data!$F$2:$F$21,"Delivered")/B10,0) -> 0.33333333 | E10: =AVERAGEIF(Data!$C$2:$C$21,A10,Data!$G$2:$G$21) -> 9.6666667
A11: Delhi | B11: =COUNTIF(Data!$C$2:$C$21,A11) -> 3 | C11: =SUMIF(Data!$C$2:$C$21,A11,Data!$E$2:$E$21) -> 8 | D11: =IFERROR(COUNTIFS(Data!$C$2:$C$21,A11,Data!$F$2:$F$21,"Delivered")/B11,0) -> 0.66666667 | E11: =AVERAGEIF(Data!$C$2:$C$21,A11,Data!$G$2:$G$21) -> 6
A12: Hyderabad | B12: =COUNTIF(Data!$C$2:$C$21,A12) -> 1 | C12: =SUMIF(Data!$C$2:$C$21,A12,Data!$E$2:$E$21) -> 1 | D12: =IFERROR(COUNTIFS(Data!$C$2:$C$21,A12,Data!$F$2:$F$21,"Delivered")/B12,0) -> 1 | E12: =AVERAGEIF(Data!$C$2:$C$21,A12,Data!$G$2:$G$21) -> 3
A13: Kolkata | B13: =COUNTIF(Data!$C$2:$C$21,A13) -> 2 | C13: =SUMIF(Data!$C$2:$C$21,A13,Data!$E$2:$E$21) -> 2 | D13: =IFERROR(COUNTIFS(Data!$C$2:$C$21,A13,Data!$F$2:$F$21,"Delivered")/B13,0) -> 1 | E13: =AVERAGEIF(Data!$C$2:$C$21,A13,Data!$G$2:$G$21) -> 4.5
A14: Mumbai | B14: =COUNTIF(Data!$C$2:$C$21,A14) -> 3 | C14: =SUMIF(Data!$C$2:$C$21,A14,Data!$E$2:$E$21) -> 9 | D14: =IFERROR(COUNTIFS(Data!$C$2:$C$21,A14,Data!$F$2:$F$21,"Delivered")/B14,0) -> 0.33333333 | E14: =AVERAGEIF(Data!$C$2:$C$21,A14,Data!$G$2:$G$21) -> 9.6666667
A15: Pune | B15: =COUNTIF(Data!$C$2:$C$21,A15) -> 6 | C15: =SUMIF(Data!$C$2:$C$21,A15,Data!$E$2:$E$21) -> 16 | D15: =IFERROR(COUNTIFS(Data!$C$2:$C$21,A15,Data!$F$2:$F$21,"Delivered")/B15,0) -> 0.33333333 | E15: =AVERAGEIF(Data!$C$2:$C$21,A15,Data!$G$2:$G$21) -> 5.8333333
A16: Total / Average | B16: =SUM(B9:B15) -> 20 | C16: =SUM(C9:C15) -> 54 | D16: =COUNTIF(Data!$F$2:$F$21,"Delivered")/COUNTA(Data!$A$2:$A$21) -> 0.55 | E16: =AVERAGE(Data!$G$2:$G$21) -> 6.6
A19: Table 2 — Delivery Status Mix
A21: Status | B21: Orders | C21: Share
A22: Delivered | B22: =COUNTIF(Data!$F$2:$F$21,A22) -> 11 | C22: =B22/SUM($B$22:$B$25) -> 0.55
A23: Pending | B23: =COUNTIF(Data!$F$2:$F$21,A23) -> 5 | C23: =B23/SUM($B$22:$B$25) -> 0.25
A24: Cancelled | B24: =COUNTIF(Data!$F$2:$F$21,A24) -> 2 | C24: =B24/SUM($B$22:$B$25) -> 0.1
A25: Returned | B25: =COUNTIF(Data!$F$2:$F$21,A25) -> 2 | C25: =B25/SUM($B$22:$B$25) -> 0.1
A26: Total | B26: =SUM(B22:B25) -> 20 | C26: =SUM(C22:C25) -> 1
A27: Table 3 — Product Performance
A29: Product | B29: Orders | C29: Quantity | D29: Avg Delivery Days
A30: Keyboard | B30: =COUNTIF(Data!$D$2:$D$21,A30) -> 3 | C30: =SUMIF(Data!$D$2:$D$21,A30,Data!$E$2:$E$21) -> 4 | D30: =AVERAGEIF(Data!$D$2:$D$21,A30,Data!$G$2:$G$21) -> 4.3333333
A31: Laptop | B31: =COUNTIF(Data!$D$2:$D$21,A31) -> 5 | C31: =SUMIF(Data!$D$2:$D$21,A31,Data!$E$2:$E$21) -> 9 | D31: =AVERAGEIF(Data!$D$2:$D$21,A31,Data!$G$2:$G$21) -> 5.8
A32: Monitor | B32: =COUNTIF(Data!$D$2:$D$21,A32) -> 3 | C32: =SUMIF(Data!$D$2:$D$21,A32,Data!$E$2:$E$21) -> 4 | D32: =AVERAGEIF(Data!$D$2:$D$21,A32,Data!$G$2:$G$21) -> 3
A33: Mouse | B33: =COUNTIF(Data!$D$2:$D$21,A33) -> 4 | C33: =SUMIF(Data!$D$2:$D$21,A33,Data!$E$2:$E$21) -> 25 | D33: =AVERAGEIF(Data!$D$2:$D$21,A33,Data!$G$2:$G$21) -> 10.75
A34: Phone | B34: =COUNTIF(Data!$D$2:$D$21,A34) -> 3 | C34: =SUMIF(Data!$D$2:$D$21,A34,Data!$E$2:$E$21) -> 7 | D34: =AVERAGEIF(Data!$D$2:$D$21,A34,Data!$G$2:$G$21) -> 6
A35: Tablet | B35: =COUNTIF(Data!$D$2:$D$21,A35) -> 2 | C35: =SUMIF(Data!$D$2:$D$21,A35,Data!$E$2:$E$21) -> 5 | D35: =AVERAGEIF(Data!$D$2:$D$21,A35,Data!$G$2:$G$21) -> 10
A36: Total / Average | B36: =SUM(B30:B35) -> 20 | C36: =SUM(C30:C35) -> 54 | D36: =AVERAGE(Data!$G$2:$G$21) -> 6.6
A39: Table 4 — City by Status
A41: City | B41: Delivered | C41: Pending | D41: Cancelled | E41: Returned
A42: Bangalore | B42: =COUNTIFS(Data!$C$2:$C$21,$A42,Data!$F$2:$F$21,B$41) -> 2 | C42: =COUNTIFS(Data!$C$2:$C$21,$A42,Data!$F$2:$F$21,C$41) -> 0 | D42: =COUNTIFS(Data!$C$2:$C$21,$A42,Data!$F$2:$F$21,D$41) -> 0 | E42: =COUNTIFS(Data!$C$2:$C$21,$A42,Data!$F$2:$F$21,E$41) -> 0
A43: Chennai | B43: =COUNTIFS(Data!$C$2:$C$21,$A43,Data!$F$2:$F$21,B$41) -> 1 | C43: =COUNTIFS(Data!$C$2:$C$21,$A43,Data!$F$2:$F$21,C$41) -> 1 | D43: =COUNTIFS(Data!$C$2:$C$21,$A43,Data!$F$2:$F$21,D$41) -> 1 | E43: =COUNTIFS(Data!$C$2:$C$21,$A43,Data!$F$2:$F$21,E$41) -> 0
A44: Delhi | B44: =COUNTIFS(Data!$C$2:$C$21,$A44,Data!$F$2:$F$21,B$41) -> 2 | C44: =COUNTIFS(Data!$C$2:$C$21,$A44,Data!$F$2:$F$21,C$41) -> 0 | D44: =COUNTIFS(Data!$C$2:$C$21,$A44,Data!$F$2:$F$21,D$41) -> 0 | E44: =COUNTIFS(Data!$C$2:$C$21,$A44,Data!$F$2:$F$21,E$41) -> 1
A45: Hyderabad | B45: =COUNTIFS(Data!$C$2:$C$21,$A45,Data!$F$2:$F$21,B$41) -> 1 | C45: =COUNTIFS(Data!$C$2:$C$21,$A45,Data!$F$2:$F$21,C$41) -> 0 | D45: =COUNTIFS(Data!$C$2:$C$21,$A45,Data!$F$2:$F$21,D$41) -> 0 | E45: =COUNTIFS(Data!$C$2:$C$21,$A45,Data!$F$2:$F$21,E$41) -> 0
A46: Kolkata | B46: =COUNTIFS(Data!$C$2:$C$21,$A46,Data!$F$2:$F$21,B$41) -> 2 | C46: =COUNTIFS(Data!$C$2:$C$21,$A46,Data!$F$2:$F$21,C$41) -> 0 | D46: =COUNTIFS(Data!$C$2:$C$21,$A46,Data!$F$2:$F$21,D$41) -> 0 | E46: =COUNTIFS(Data!$C$2:$C$21,$A46,Data!$F$2:$F$21,E$41) -> 0
A47: Mumbai | B47: =COUNTIFS(Data!$C$2:$C$21,$A47,Data!$F$2:$F$21,B$41) -> 1 | C47: =COUNTIFS(Data!$C$2:$C$21,$A47,Data!$F$2:$F$21,C$41) -> 2 | D47: =COUNTIFS(Data!$C$2:$C$21,$A47,Data!$F$2:$F$21,D$41) -> 0 | E47: =COUNTIFS(Data!$C$2:$C$21,$A47,Data!$F$2:$F$21,E$41) -> 0
A48: Pune | B48: =COUNTIFS(Data!$C$2:$C$21,$A48,Data!$F$2:$F$21,B$41) -> 2 | C48: =COUNTIFS(Data!$C$2:$C$21,$A48,Data!$F$2:$F$21,C$41) -> 2 | D48: =COUNTIFS(Data!$C$2:$C$21,$A48,Data!$F$2:$F$21,D$41) -> 1 | E48: =COUNTIFS(Data!$C$2:$C$21,$A48,Data!$F$2:$F$21,E$41) -> 1
A49: Total | B49: =SUM(B42:B48) -> 11 | C49: =SUM(C42:C48) -> 5 | D49: =SUM(D42:D48) -> 2 | E49: =SUM(E42:E48) -> 2
...

Sheet Pivot Analysis
A1: Pivot Analysis Dashboard
A2: KPI Summary
A3: Average of Delivery_Days | B3: Average of Quantity | C3: Count of Order_ID | D3: Cancelled | E3: Delivered | F3: Pending | G3: Returned
A4: 6.6 | B4: 2.7 | C4: 20 | D4: 10 | E4: 55 | F4: 25 | G4: 10
A6: =GETPIVOTDATA("Average of Delivery_Days",$A$3) -> 6.6 | B6: =GETPIVOTDATA("Average of Quantity",$A$3) -> 2.7 | C6: =GETPIVOTDATA("Count of Order_ID",$A$3) -> 20 | D6: =D4 -> 10 | E6: =E4 -> 55 | F6: =F4 -> 25 | G6: =G4 -> 10
A9: Delivery Performance by Product
A10: Row Labels | B10: Average of Delivery_Days
A11: Keyboard | B11: 4.3333333
A12: Laptop | B12: 5.8
A13: Monitor | B13: 3
A14: Mouse | B14: 10.75
A15: Phone | B15: 6
A16: Tablet | B16: 10
A17: Grand Total | B17: 6.6
A20: Delivery Performance by City
A21: Row Labels | B21: Average of Delivery_Days
A22: Bangalore | B22: 4.5
A23: Chennai | B23: 9.6666667
A24: Delhi | B24: 6
A25: Hyderabad | B25: 3
A26: Kolkata | B26: 4.5
A27: Mumbai | B27: 9.6666667
A28: Pune | B28: 5.8333333
A29: Grand Total | B29: 6.6
A32: Orders by Status
A33: Row Labels | B33: Count of Order_ID
A34: Cancelled | B34: 2
A35: Delivered | B35: 11
A36: Pending | B36: 5
A37: Returned | B37: 2
A38: Grand Total | B38: 20
A41: Product Mix by Order Share
A42: Row Labels | B42: Count of Order_ID
A43: Keyboard | B43: 0.15
A44: Laptop | B44: 0.25
A45: Monitor | B45: 0.15
A46: Mouse | B46: 0.2
A47: Phone | B47: 0.15
A48: Tablet | B48: 0.1
A49: Grand Total | B49: 1

Sheet Dashbored 
